Traceback (most recent call last):
  File "<frozen runpy>", line 198, in _run_module_as_main
  File "<frozen runpy>", line 88, in _run_code
  File "C:\Users\listonianapp\AppData\Local\Programs\Python\Python312\Scripts\uvicorn.exe\__main__.py", line 7, in <module>
  File "C:\Users\listonianapp\AppData\Local\Programs\Python\Python312\Lib\site-packages\click\core.py", line 1161, in __call__
    return self.main(*args, **kwargs)
           ^^^^^^^^^^^^^^^^^^^^^^^^^^
  File "C:\Users\listonianapp\AppData\Local\Programs\Python\Python312\Lib\site-packages\click\core.py", line 1082, in main
    rv = self.invoke(ctx)
         ^^^^^^^^^^^^^^^^
  File "C:\Users\listonianapp\AppData\Local\Programs\Python\Python312\Lib\site-packages\click\core.py", line 1443, in invoke
    return ctx.invoke(self.callback, **ctx.params)
           ^^^^^^^^^^^^^^^^^^^^^^^^^^^^^^^^^^^^^^^
  File "C:\Users\listonianapp\AppData\Local\Programs\Python\Python312\Lib\site-packages\click\core.py", line 788, in invoke
    return __callback(*args, **kwargs)
           ^^^^^^^^^^^^^^^^^^^^^^^^^^^
  File "C:\Users\listonianapp\AppData\Local\Programs\Python\Python312\Lib\site-packages\uvicorn\main.py", line 412, in main
    run(
  File "C:\Users\listonianapp\AppData\Local\Programs\Python\Python312\Lib\site-packages\uvicorn\main.py", line 579, in run
    server.run()
  File "C:\Users\listonianapp\AppData\Local\Programs\Python\Python312\Lib\site-packages\uvicorn\server.py", line 66, in run
    return asyncio.run(self.serve(sockets=sockets))
           ^^^^^^^^^^^^^^^^^^^^^^^^^^^^^^^^^^^^^^^^
  File "C:\Users\listonianapp\AppData\Local\Programs\Python\Python312\Lib\asyncio\runners.py", line 194, in run
    return runner.run(main)
           ^^^^^^^^^^^^^^^^
  File "C:\Users\listonianapp\AppData\Local\Programs\Python\Python312\Lib\asyncio\runners.py", line 118, in run
    return self._loop.run_until_complete(task)
           ^^^^^^^^^^^^^^^^^^^^^^^^^^^^^^^^^^^
  File "C:\Users\listonianapp\AppData\Local\Programs\Python\Python312\Lib\asyncio\base_events.py", line 685, in run_until_complete
    return future.result()
           ^^^^^^^^^^^^^^^
  File "C:\Users\listonianapp\AppData\Local\Programs\Python\Python312\Lib\site-packages\uvicorn\server.py", line 70, in serve
    await self._serve(sockets)
  File "C:\Users\listonianapp\AppData\Local\Programs\Python\Python312\Lib\site-packages\uvicorn\server.py", line 77, in _serve
    config.load()
  File "C:\Users\listonianapp\AppData\Local\Programs\Python\Python312\Lib\site-packages\uvicorn\config.py", line 435, in load
    self.loaded_app = import_from_string(self.app)
                      ^^^^^^^^^^^^^^^^^^^^^^^^^^^^
  File "C:\Users\listonianapp\AppData\Local\Programs\Python\Python312\Lib\site-packages\uvicorn\importer.py", line 19, in import_from_string
    module = importlib.import_module(module_str)
             ^^^^^^^^^^^^^^^^^^^^^^^^^^^^^^^^^^^
  File "C:\Users\listonianapp\AppData\Local\Programs\Python\Python312\Lib\importlib\__init__.py", line 90, in import_module
    return _bootstrap._gcd_import(name[level:], package, level)
           ^^^^^^^^^^^^^^^^^^^^^^^^^^^^^^^^^^^^^^^^^^^^^^^^^^^^
  File "<frozen importlib._bootstrap>", line 1387, in _gcd_import
  File "<frozen importlib._bootstrap>", line 1360, in _find_and_load
  File "<frozen importlib._bootstrap>", line 1310, in _find_and_load_unlocked
  File "<frozen importlib._bootstrap>", line 488, in _call_with_frames_removed
  File "<frozen importlib._bootstrap>", line 1387, in _gcd_import
  File "<frozen importlib._bootstrap>", line 1360, in _find_and_load
  File "<frozen importlib._bootstrap>", line 1310, in _find_and_load_unlocked
  File "<frozen importlib._bootstrap>", line 488, in _call_with_frames_removed
  File "<frozen importlib._bootstrap>", line 1387, in _gcd_import
  File "<frozen importlib._bootstrap>", line 1360, in _find_and_load
  File "<frozen importlib._bootstrap>", line 1331, in _find_and_load_unlocked
  File "<frozen importlib._bootstrap>", line 935, in _load_unlocked
  File "<frozen importlib._bootstrap_external>", line 995, in exec_module
  File "<frozen importlib._bootstrap>", line 488, in _call_with_frames_removed
  File "F:\Arby 2-22-25\Listonian-bot\new_dashboard\__init__.py", line 3, in <module>
    from .dashboard import app
  File "F:\Arby 2-22-25\Listonian-bot\new_dashboard\dashboard\__init__.py", line 3, in <module>
    from .app import app
  File "F:\Arby 2-22-25\Listonian-bot\new_dashboard\dashboard\app.py", line 14, in <module>
    from .core.logging import configure_logging, get_logger
  File "F:\Arby 2-22-25\Listonian-bot\new_dashboard\dashboard\core\__init__.py", line 4, in <module>
    from .dependencies import get_memory_service, get_metrics_service, get_system_service
  File "F:\Arby 2-22-25\Listonian-bot\new_dashboard\dashboard\core\dependencies.py", line 3, in <module>
    from ..services.service_manager import service_manager
  File "F:\Arby 2-22-25\Listonian-bot\new_dashboard\dashboard\services\__init__.py", line 5, in <module>
    from .system_service import SystemService
  File "F:\Arby 2-22-25\Listonian-bot\new_dashboard\dashboard\services\system_service.py", line 12, in <module>
    from arbitrage_bot.core.memory.memory_bank import MemoryBank
  File "F:\Arby 2-22-25\Listonian-bot\arbitrage_bot\__init__.py", line 11, in <module>
    from .core.market import EnhancedMarketAnalyzer, PriceValidator
  File "F:\Arby 2-22-25\Listonian-bot\arbitrage_bot\core\__init__.py", line 16, in <module>
    from .unified_flash_loan_manager import EnhancedFlashLoanManager
  File "F:\Arby 2-22-25\Listonian-bot\arbitrage_bot\core\unified_flash_loan_manager.py", line 20, in <module>
    from .web3.flashbots.flashbots_provider import FlashbotsProvider
  File "F:\Arby 2-22-25\Listonian-bot\arbitrage_bot\core\web3\flashbots\__init__.py", line 11, in <module>
    from .risk_analyzer import RiskAnalyzer
  File "F:\Arby 2-22-25\Listonian-bot\arbitrage_bot\core\web3\flashbots\risk_analyzer.py", line 19, in <module>
    from arbitrage_bot.core import Web3Error
ImportError: cannot import name 'Web3Error' from partially initialized module 'arbitrage_bot.core' (most likely due to a circular import) (F:\Arby 2-22-25\Listonian-bot\arbitrage_bot\core\__init__.py)
